<?xml version="1.0" encoding="utf-8"?>
<!-- This URDF was automatically created by SolidWorks to URDF Exporter! Originally created by Stephen Brawner (brawner@gmail.com) 
     Commit Version: 1.5.1-0-g916b5db  Build Version: 1.5.7152.31018
     For more information, please see http://wiki.ros.org/sw_urdf_exporter -->
<robot name="turn_table" xmlns:xacro="http://www.ros.org/wiki/xacro">
  <xacro:include filename="$(find turn_table_robot)/urdf/turn_table.gazebo" />
  <gazebo reference="rotation_Link">
       <material>Gazebo/Blue</material>
    </gazebo>
  <link name="base">
    <inertial>
      <origin xyz="5.47630436823313 0.00445137401296207 0.127274647707627" rpy="0 0 0" />
      <mass value="53" />
      <inertia
        ixx="4.69052174516768"
        ixy="-2.85464416367111E-06"
        ixz="6.14968020065979E-06"
        iyy="11.0842686073968"
        iyz="-1.23849027826522E-05"
        izz="7.82834235009259" /> 
    </inertial>
    <visual>
      <origin
        xyz="-0.147933831436891 -5.47629333274696 0"
        rpy="0 0 1.57079" />
      <geometry>
        <mesh
          filename="package://turn_table_robot/meshes/base_link.STL" />
      </geometry>
    </visual>
    <collision>
      <origin
        xyz="0 0 0"
        rpy="0 0 0" />
      <geometry>
        <mesh
          filename="package://turn_table_robot/meshes/base_link.STL" />
      </geometry>
    </collision>
  </link>
 <link name="controller_box">
    <collision>
      <origin rpy="0 0 0" xyz="-0.325 0 -0.38"/>
      <geometry>
        <box size="0.22 0.4 0.53"/>
      </geometry>
    </collision>
  </link>
  <joint name="controller_box_fixed" type="fixed">
    <origin rpy="0 0 0" xyz="0.0 0.0 0.0"/>
    <parent link="base"/>
    <child link="controller_box"/>
  </joint>
 
  <link
    name="rotation_Link">
    <inertial>
      <origin
        xyz="-9.32587340685131E-14 -9.32032229172819E-14 0.0772872732553641"
        rpy="0 0 0" />
      <mass
        value="4.54714819339239" />
      <inertia
        ixx="0.0677428262810966"
        ixy="-3.53126796518736E-18"
        ixz="-8.0168446404932E-14"
        iyy="0.0677428262810966"
        iyz="-8.07156753739356E-14"
        izz="0.134697984247435" />
    </inertial>
    <visual>
      <origin
        xyz="0 0 0.228567473840997"
        rpy="0 0 0" />
      <geometry>
        <mesh
          filename="package://turn_table_robot/meshes/rotation_Link.STL" />
      </geometry>
      <material
        name="">
        <color
          rgba="0.792156862745098 0.819607843137255 0.933333333333333 1" />
      </material>
    </visual>
    <collision>
      <origin
        xyz="0 0 0.228567473840997"
        rpy="0 0 0" />
      <geometry>
        <mesh
          filename="package://turn_table_robot/meshes/rotation_Link.STL" />
      </geometry>
    </collision>
  </link>
  <joint
    name="joint"
    type="revolute">
    <origin
      xyz="0 0 0"
      rpy="0 0 0" />
    <parent
      link="base" />
    <child
      link="rotation_Link" />
    <axis
      xyz="0 0 1" />
    <limit effort="1000.0" lower="-3.14" upper="3.14" velocity="0.5"/>
    <dynamics damping="0.7" />
  </joint>
 
  <!-- transmission -->
  <transmission name="trans">
    <type>transmission_interface/SimpleTransmission</type>
    <joint name="joint">
      <hardwareInterface>hardware_interface/EffortJointInterface</hardwareInterface>
    </joint>
    <actuator name="motor">
      <hardwareInterface>hardware_interface/EffortJointInterface</hardwareInterface>
      <mechanicalReduction>1</mechanicalReduction>
    </actuator>
  </transmission>
  
</robot>
